<robot name = "robot">
    <link name="Link0">
        <inertial>
            <origin xyz="0 0 0.5" rpy="0 0 0"/>
            <mass value="1" />
            <inertia ixx="100" ixy="0" ixz="0" iyy="100" iyz="0" izz="100" />
        </inertial>
        <visual>
            <origin xyz="0 0 0.5" rpy="0 0 0"/>
            <geometry>
                <box size="1 1 1" />
            </geometry>
            <material name="Cyan">
                <color rgba="0 1.0 1.0 1.0"/>
            </material>
        </visual>
        <collision>
            <origin xyz="0 0 0.5" rpy="0 0 0"/>
            <geometry>
                <box size="1 1 1" />
            </geometry>
        </collision>
    </link>
    <link name="Link1">
        <inertial>
            <origin xyz="0 0 0.5" rpy="0 0 0"/>
            <mass value="1" />
            <inertia ixx="100" ixy="0" ixz="0" iyy="100" iyz="0" izz="100" />
        </inertial>
        <visual>
            <origin xyz="0 0 0.5" rpy="0 0 0"/>
            <geometry>
                <box size="1 1 1" />
            </geometry>
            <material name="Cyan">
                <color rgba="0 1.0 1.0 1.0"/>
            </material>
        </visual>
        <collision>
            <origin xyz="0 0 0.5" rpy="0 0 0"/>
            <geometry>
                <box size="1 1 1" />
            </geometry>
        </collision>
    </link>
    <link name="Link2">
        <inertial>
            <origin xyz="0 0 0.5" rpy="0 0 0"/>
            <mass value="1" />
            <inertia ixx="100" ixy="0" ixz="0" iyy="100" iyz="0" izz="100" />
        </inertial>
        <visual>
            <origin xyz="0 0 0.5" rpy="0 0 0"/>
            <geometry>
                <box size="1 1 1" />
            </geometry>
            <material name="Cyan">
                <color rgba="0 1.0 1.0 1.0"/>
            </material>
        </visual>
        <collision>
            <origin xyz="0 0 0.5" rpy="0 0 0"/>
            <geometry>
                <box size="1 1 1" />
            </geometry>
        </collision>
    </link>
    <link name="Link3">
        <inertial>
            <origin xyz="0 0.5 0" rpy="0 0 0"/>
            <mass value="1" />
            <inertia ixx="100" ixy="0" ixz="0" iyy="100" iyz="0" izz="100" />
        </inertial>
        <visual>
            <origin xyz="0 0.5 0" rpy="0 0 0"/>
            <geometry>
                <box size="1 1 1" />
            </geometry>
            <material name="Cyan">
                <color rgba="0 1.0 1.0 1.0"/>
            </material>
        </visual>
        <collision>
            <origin xyz="0 0.5 0" rpy="0 0 0"/>
            <geometry>
                <box size="1 1 1" />
            </geometry>
        </collision>
    </link>
    <link name="Link4">
        <inertial>
            <origin xyz="0 0.5 0" rpy="0 0 0"/>
            <mass value="1" />
            <inertia ixx="100" ixy="0" ixz="0" iyy="100" iyz="0" izz="100" />
        </inertial>
        <visual>
            <origin xyz="0 0.5 0" rpy="0 0 0"/>
            <geometry>
                <box size="1 1 1" />
            </geometry>
            <material name="Cyan">
                <color rgba="0 1.0 1.0 1.0"/>
            </material>
        </visual>
        <collision>
            <origin xyz="0 0.5 0" rpy="0 0 0"/>
            <geometry>
                <box size="1 1 1" />
            </geometry>
        </collision>
    </link>
    <link name="Link5">
        <inertial>
            <origin xyz="0 0 -0.5" rpy="0 0 0"/>
            <mass value="1" />
            <inertia ixx="100" ixy="0" ixz="0" iyy="100" iyz="0" izz="100" />
        </inertial>
        <visual>
            <origin xyz="0 0 -0.5" rpy="0 0 0"/>
            <geometry>
                <box size="1 1 1" />
            </geometry>
            <material name="Cyan">
                <color rgba="0 1.0 1.0 1.0"/>
            </material>
        </visual>
        <collision>
            <origin xyz="0 0 -0.5" rpy="0 0 0"/>
            <geometry>
                <box size="1 1 1" />
            </geometry>
        </collision>
    </link>
    <link name="Link6">
        <inertial>
            <origin xyz="0 0 -0.5" rpy="0 0 0"/>
            <mass value="1" />
            <inertia ixx="100" ixy="0" ixz="0" iyy="100" iyz="0" izz="100" />
        </inertial>
        <visual>
            <origin xyz="0 0 -0.5" rpy="0 0 0"/>
            <geometry>
                <box size="1 1 1" />
            </geometry>
            <material name="Cyan">
                <color rgba="0 1.0 1.0 1.0"/>
            </material>
        </visual>
        <collision>
            <origin xyz="0 0 -0.5" rpy="0 0 0"/>
            <geometry>
                <box size="1 1 1" />
            </geometry>
        </collision>
    </link>
    <joint name="Link0_Link1" type="revolute">
       <parent link="Link0"/>
       <child  link="Link1"/>
       <origin rpy="0 0 0" xyz="0 0 1" />
       <axis xyz="0 1 0"/>
       <limit effort="0.0" lower="-3.14159" upper="3.14159" velocity="0.0"/>
    </joint>
    <joint name="Link1_Link2" type="revolute">
       <parent link="Link1"/>
       <child  link="Link2"/>
       <origin rpy="0 0 0" xyz="0 0 1" />
       <axis xyz="0 1 0"/>
       <limit effort="0.0" lower="-3.14159" upper="3.14159" velocity="0.0"/>
    </joint>
    <joint name="Link2_Link3" type="revolute">
       <parent link="Link2"/>
       <child  link="Link3"/>
       <origin rpy="0 0 0" xyz="0 0.5 0.5" />
       <axis xyz="0 1 0"/>
       <limit effort="0.0" lower="-3.14159" upper="3.14159" velocity="0.0"/>
    </joint>
    <joint name="Link3_Link4" type="revolute">
       <parent link="Link3"/>
       <child  link="Link4"/>
       <origin rpy="0 0 0" xyz="0 0.5 0" />
       <axis xyz="0 1 0"/>
       <limit effort="0.0" lower="-3.14159" upper="3.14159" velocity="0.0"/>
    </joint>
    <joint name="Link4_Link5" type="revolute">
       <parent link="Link4"/>
       <child  link="Link5"/>
       <origin rpy="0 0 0" xyz="0 0.5 -0.5" />
       <axis xyz="0 1 0"/>
       <limit effort="0.0" lower="-3.14159" upper="3.14159" velocity="0.0"/>
    </joint>
    <joint name="Link5_Link6" type="revolute">
       <parent link="Link5"/>
       <child  link="Link6"/>
       <origin rpy="0 0 0" xyz="0 0 -1" />
       <axis xyz="0 1 0"/>
       <limit effort="0.0" lower="-3.14159" upper="3.14159" velocity="0.0"/>
    </joint>
</robot>